Workbook

Sheet Report
A1: Serial Num | B1: Calibration SW Ver | C1: Cal Data File Ver | D1: Mag SW Ver | E1: Date | F1: Time
A2: 1475 | B2: 2.0.0.0 | C2: 0 | D2: 1 | E2: 42432 | F2: 0.44696759
A4: Step | B4: Description | C4: Axis | D4: Offset | E4: ScaleFactor | F4: Desired | G4: Actual | H4: Tolerance | I4: Retries | J4: Pass | K4: Fail
A5: 1 | B5: Xm,XrYm, Yr.(Zm, | E5: -9120 | F5: 4217 | G5: -14596
A6: =A5+1 -> 2 | B6: Xm, Yr),Ym,-Xr,Zm | E6: 2792 | F6: 8970 | G6: -14735
A7: =A6+1 -> 3 | B7: (Xm,Xr),Ym,-Yr,(Zm, | E7: 8688 | F7: -3796 | G7: -14324
A8: =A7+1 -> 4 | B8: (Xm,Yr,Ym, XrZm, | E8: -3171 | F8: -8531 | G8: -14167
A9: =A8+1 -> 5 | B9: Xm, Xr,Ym,Yr, | E9: -8984 | F9: -3094 | G9: 13247
A10: =A9+1 -> 6 | B10: (Xm, Yr,(Ym, Xr, | E10: 3476 | F10: -9202 | G10: 13621
A11: =A10+1 -> 7 | B11: (Xm-Xr, (Ym,Yr,f | E11: 8199 | F11: 2952 | G11: 13177
A12: =A11+1 -> 8 | B12: (Xm,-Yr), (Ym,-Xr 1, ( | E12: -4261 | F12: 9034 | G12: 12865
A13: =A12+1 -> 9 | B13: (Xm,XrYm,Zr | E13: -8358 | F13: -13478 | G13: -3683
A14: =A13+1 -> 10 | B14: (Xm, Yr , f Ym, Zr), ( Zm | E14: 3924 | F14: -14281 | G14: -8738
A15: =A14+1 -> 11 | B15: (Xm,-Xr ), f Ym, Zr 3, ( Zm, | E15: 9068 | F15: -14598 | G15: 3468
A16: =A15+1 -> 12 | E16: -3144 | F16: -13840 | G16: 8698
A17: =A16+1 -> 13 | B17: (Xm,-Yr, Ym, Zr , (
A18: =A17+1 -> 14 | B18: ( Xm, Xr), (Ym,-Zr , ( Zm, | E18: -9760 | F18: 14551 | G18: 2393
A19: =A18+1 -> 15 | E19: 2388 | F19: 13930.001 | G19: 7673
A20: =A19+1 -> 16 | B20: (Xm, Yr), (Ym,-Zr, (
A21: =A20+1 -> 17 | B21: Xm-XrYm,-Zr, | E21: 7692 | F21: 13725.001 | G21: -4439
A22: =A21+1 -> 18 | B22: (Xm-Yr,Ym,-Zr,(Zm, | E22: -4390 | F22: 14343 | G22: -9876
A23: =A22+1 -> 19 | B23: Xm,Zr,Ym,Yr, | E23: -14329 | F23: 4200 | G23: 7794
A24: =A23+1 -> 20 | B24: (Xm,Zr,Ym,-Xr | E24: -14464 | F24: 9744 | G24: -4506
A25: =A24+1 -> 21 | B25: I Xm, Zr 1, I Ym,-Yr I, f Zm | E25: -13839 | F25: -2599 | G25: -9378
A26: =A25+1 -> 22 | B26: Xm,Zr,Ym,Xr,Zm, | E26: -13644 | F26: -8126 | G26: 2964
A27: =A26+1 -> 23 | B27: Xm,-Zr,(Ym,Yri,Zm, | E27: 13357 | F27: 2980 | G27: -9338
A28: =A27+1 -> 24 | B28: Xm,-Zr , ( Ym,-Xr1, ( Zm, | E28: 13045 | F28: 8254 | G28: 2701
A29: =A28+1 -> 25 | B29: ( Xm,-Zr l, ( Ym,-Yr I, t | E29: 13780 | F29: -4306 | G29: 8313
A30: =A29+1 -> 26 | B30: Xm-ZrYm,Xr | E30: 14021 | F30: -9516 | G30: -3759
A31: =A30+1 -> 27
A32: =A31+1 -> 28 | B32: Calculating Offsets and CalculatingScale Factors
A33: =A32+1 -> 29 | B33: Test Offset | D33: 293 | G33: 2207 | H33: 2500
A34: =A33+1 -> 30 | B34: Test Offset | D34: -63 | G34: 2437 | H34: 2500
A35: =A34+1 -> 31 | B35: Test Offset | D35: 609 | G35: 1891 | H35: 2500
A36: =A35+1 -> 32 | B36: sxx | C36: XX | E36: 0 | F36: 0 | G36: 10 | H36: 10
A37: =A36+1 -> 33 | B37: sxy | C37: XY | E37: -4.973 | F37: 0 | G37: 5.027 | H37: 10
A38: =A37+1 -> 34 | B38: sxz | E38: -0.636 | F38: 0 | G38: 9.364 | H38: 10
A39: =A38+1 -> 35 | B39: syx | E39: -5.262 | F39: 0 | G39: 4.738 | H39: 10 | J39: X
A40: =A39+1 -> 36 | B40: syy | E40: 2.043 | F40: 0 | G40: 7.957 | H40: 10
A41: =A40+1 -> 37 | B41: syz | E41: -0.943 | F41: 0 | G41: 9.057 | H41: 10
...

Sheet Plot
A17: Scale Factors Data | G17: Scale Factors Chart Data
A18: Label | B18: Axis Group | C18: Component | D18: ScaleFactor | E18: Actual | G18: Component | H18: X ScaleFactor | I18: X Actual | J18: Y ScaleFactor | K18: Y Actual | L18: Z ScaleFactor | M18: Z Actual
A19: =Report!B36 -> sxx | B19: X | C19: xx | D19: =Report!E36 -> 0 | E19: =Report!G36 -> 10 | G19: s_x | H19: =Report!E36 -> 0 | I19: =Report!G36 -> 10 | J19: =Report!E39 -> -5.262 | K19: =Report!G39 -> 4.738 | L19: =Report!E42 -> 0.894 | M19: =Report!G42 -> 9.106
A20: =Report!B37 -> sxy | B20: X | C20: xy | D20: =Report!E37 -> -4.973 | E20: =Report!G37 -> 5.027 | G20: s_y | H20: =Report!E37 -> -4.973 | I20: =Report!G37 -> 5.027 | J20: =Report!E40 -> 2.043 | K20: =Report!G40 -> 7.957 | L20: =Report!E43 -> -3.434 | M20: =Report!G43 -> 6.566
A21: =Report!B38 -> sxz | B21: X | C21: xz | D21: =Report!E38 -> -0.636 | E21: =Report!G38 -> 9.364 | G21: s_z | H21: =Report!E38 -> -0.636 | I21: =Report!G38 -> 9.364 | J21: =Report!E41 -> -0.943 | K21: =Report!G41 -> 9.057 | L21: =Report!E44 -> 0.189 | M21: =Report!G44 -> 9.811
A22: =Report!B39 -> syx | B22: Y | C22: yx | D22: =Report!E39 -> -5.262 | E22: =Report!G39 -> 4.738
A23: =Report!B40 -> syy | B23: Y | C23: yy | D23: =Report!E40 -> 2.043 | E23: =Report!G40 -> 7.957
A24: =Report!B41 -> syz | B24: Y | C24: yz | D24: =Report!E41 -> -0.943 | E24: =Report!G41 -> 9.057
A25: =Report!B42 -> szx | B25: Z | C25: zx | D25: =Report!E42 -> 0.894 | E25: =Report!G42 -> 9.106
A26: =Report!B43 -> szy | B26: Z | C26: zy | D26: =Report!E43 -> -3.434 | E26: =Report!G43 -> 6.566
A27: =Report!B44 -> szz | B27: Z | C27: zz | D27: =Report!E44 -> 0.189 | E27: =Report!G44 -> 9.811
A46: Cardinal Orientation Data | G46: Cardinal Orientation Chart Data
A47: Label | B47: Axis Group | C47: Component | D47: ScaleFactor | E47: Actual | G47: Component | H47: X ScaleFactor | I47: X Actual | J47: Y ScaleFactor | K47: Y Actual | L47: Z ScaleFactor | M47: Z Actual
A48: =Report!B46 -> xsd | B48: X | C48: xsd | D48: =Report!E46 -> 19.949 | E48: =Report!G46 -> 180.051 | G48: sd | H48: =Report!E46 -> 19.949 | I48: =Report!G46 -> 180.051 | J48: =Report!E47 -> 27.394 | K48: =Report!G47 -> 172.606 | L48: =Report!E48 -> 18.202 | M48: =Report!G48 -> 181.798
A49: =Report!B49 -> exx | B49: X | C49: exx | D49: =Report!E49 -> 50.221 | E49: =Report!G49 -> 149.779 | G49: e_x | H49: =Report!E49 -> 50.221 | I49: =Report!G49 -> 149.779 | J49: =Report!E52 -> 40.435 | K49: =Report!G52 -> 159.565 | L49: =Report!E55 -> 72.276 | M49: =Report!G55 -> 127.724
A50: =Report!B50 -> exy | B50: X | C50: exy | D50: =Report!E50 -> 31.421 | E50: =Report!G50 -> 168.579 | G50: e_y | H50: =Report!E50 -> 31.421 | I50: =Report!G50 -> 168.579 | J50: =Report!E53 -> 36.774 | K50: =Report!G53 -> 163.226 | L50: =Report!E56 -> 82.064 | M50: =Report!G56 -> 117.936
A51: =Report!B51 -> exz | B51: X | C51: exz | D51: =Report!E51 -> 74.768 | E51: =Report!G51 -> 125.232 | G51: e_z | H51: =Report!E51 -> 74.768 | I51: =Report!G51 -> 125.232 | J51: =Report!E54 -> 92.954 | K51: =Report!G54 -> 107.046 | L51: =Report!E57 -> 48.554 | M51: =Report!G57 -> 151.446
A52: =Report!B47 -> ysd | B52: Y | C52: ysd | D52: =Report!E47 -> 27.394 | E52: =Report!G47 -> 172.606
A53: =Report!B52 -> eyx | B53: Y | C53: eyx | D53: =Report!E52 -> 40.435 | E53: =Report!G52 -> 159.565
A54: =Report!B53 -> eyy | B54: Y | C54: eyy | D54: =Report!E53 -> 36.774 | E54: =Report!G53 -> 163.226
A55: =Report!B54 -> eyz | B55: Y | C55: eyz | D55: =Report!E54 -> 92.954 | E55: =Report!G54 -> 107.046
A56: =Report!B48 -> zsd | B56: Z | C56: zsd | D56: =Report!E48 -> 18.202 | E56: =Report!G48 -> 181.798
A57: =Report!B55 -> ezx | B57: Z | C57: ezx | D57: =Report!E55 -> 72.276 | E57: =Report!G55 -> 127.724
A58: =Report!B56 -> ezy | B58: Z | C58: ezy | D58: =Report!E56 -> 82.064 | E58: =Report!G56 -> 117.936
A59: =Report!B57 -> ezz | B59: Z | C59: ezz | D59: =Report!E57 -> 48.554 | E59: =Report!G57 -> 151.446
A78: Chi-Square Data | G78: Chi-Square Chart Data
A79: Label | B79: Axis Group | C79: Component | D79: ScaleFactor | E79: Actual | G79: Measure | H79: X | I79: Y | J79: Z
A80: =Report!B58 -> chisqr_x | B80: X | C80: chisqr_x | D80: =Report!E58 -> 2.613 | E80: =Report!G58 -> 1.387 | G80: ScaleFactor | H80: =Report!E58 -> 2.613 | I80: =Report!E59 -> 2.071 | J80: =Report!E60 -> 3.716
A81: =Report!B59 -> chisqr_y | B81: Y | C81: chisqr_y | D81: =Report!E59 -> 2.071 | E81: =Report!G59 -> 1.929 | G81: Actual | H81: =Report!G58 -> 1.387 | I81: =Report!G59 -> 1.929 | J81: =Report!G60 -> 0.284
A82: =Report!B60 -> chisqr_z | B82: Z | C82: chisqr_z | D82: =Report!E60 -> 3.716 | E82: =Report!G60 -> 0.284
